Workbook

Sheet TC-C.B-Fuse
D1: Enter Data in White Background Cells
C2: Calculate Size of Transformer / Fuse / Circuit Breaker | M2: Jignesh.Parmar www.electricalnotes.wordpress.com, jiguparmar@yahoo.com
D3: Calculation Size of Circuit Breaker & Fuse are as per NEC 450.3
C5: CONNECTED EQUIPMENT TO TRANSFORMER | M5: Transformer Details
C6: Sr.No | D6: Equipment | E6: Kw | F6: P.F | G6: Qty | H6: Equipment D.F | I6: Total Kva | J6: D.F (Kva) | M6: Total D.F Load | N6: =J37 -> 3 | O6: Kva | AS6: Y-Y | AT6: =IF(N10=AS6,1,IF(N10=AS7,2,IF(N10=AS8,3,4))) -> 1
E7: 3 | F7: 1 | G7: 1 | H7: 1 | I7: =IF(G7="",0,((E7/F7)*G7)) -> 3 | J7: =I7*H7 -> 3 | M7: Primary Side Voltage (L-L): | N7: 415 | O7: Volt | AO7: =IF(N7<600,0,1) -> 0 | AS7: ∆-∆ | AU7: Primary Only
I8: =IF(G8="",0,((E8/F8)*G8)) -> 0 | J8: =I8*H8 -> 0 | M8: Secondary Side Voltage (L-L): | N8: 230 | O8: Volt | AO8: =IF(N8<600,0,1) -> 0 | AS8: Y-∆ | AU8: Pri.Side & Sec.Side
I9: =IF(G9="",0,((E9/F9)*G9)) -> 0 | J9: =I9*H9 -> 0 | M9: Transformer Impedance: | N9: 0.05 | AO9: 1 | AS9: ∆-Y
I10: =IF(G10="",0,((E10/F10)*G10)) -> 0 | J10: =I10*H10 -> 0 | M10: Transformer Connection | N10: Y-Y | AO10: TRUE
I11: =IF(G11="",0,((E11/F11)*G11)) -> 0 | J11: =I11*H11 -> 0 | M11: Size of Transformer: | N11: =IF(N6=0,0,Sheet2!AQ3) -> 3 | O11: Kva OR | Q11: Kva | S11: =IF(P11="",N11,P11) -> 3 | AO11: TRUE
I12: =IF(G12="",0,((E12/F12)*G12)) -> 0 | J12: =I12*H12 -> 0 | M12: Efficency of Transformer at Full Load | N12: 0.984 | O12: =N12 -> 0.984
I13: =IF(G13="",0,((E13/F13)*G13)) -> 0 | J13: =I13*H13 -> 0 | M13: Efficency of Transformer at 1/4 Load | N13: 0.975 | O13: =N13 -> 0.975
I14: =IF(G14="",0,((E14/F14)*G14)) -> 0 | J14: =I14*H14 -> 0 | M14: Location of Transformer
I15: =IF(G15="",0,((E15/F15)*G15)) -> 0 | J15: =I15*H15 -> 0 | M15: =IF(N7<600,"Provide Protection on Transformer:","") -> Provide Protection on Transformer: | N15: Primary Only
I16: =IF(G16="",0,((E16/F16)*G16)) -> 0 | J16: =I16*H16 -> 0 | M16: Type Protection on Primary & Secondary Side: | AR16: 1 | AS16: 2 | AT16: 3 | AU16: 4
I17: =IF(G17="",0,((E17/F17)*G17)) -> 0 | J17: =I17*H17 -> 0 | M17: :Results: | AR17: 1 | AS17: 2 | AT17: 3 | AU17: 4
I18: =IF(G18="",0,((E18/F18)*G18)) -> 0 | J18: =I18*H18 -> 0 | M18: Transformer Voltage / Current | AR18: Y-Y | AS18: D-D | AT18: Y-D | AU18: D-Y
I19: =IF(G19="",0,((E19/F19)*G19)) -> 0 | J19: =I19*H19 -> 0 | M19: Primary Line Voltage (L-L) | N19: =AQ19 -> 415 | O19: Volt | AQ19: =HLOOKUP($AT$6,$AR$17:$AU$26,3,0) -> 415 | AR19: =N7 -> 415 | AS19: =N7 -> 415 | AT19: =N7 -> 415 | AU19: =AS19 -> 415
I20: =IF(G20="",0,((E20/F20)*G20)) -> 0 | J20: =I20*H20 -> 0 | M20: Primary Phase Voltage (L-P) | N20: =AQ20 -> 239.60739 | O20: Volt | AQ20: =HLOOKUP($AT$6,$AR$17:$AU$26,4,0) -> 239.60739 | AR20: =AR19/1.732 -> 239.60739 | AS20: =AS19 -> 415 | AT20: =AR20 -> 239.60739 | AU20: =AS20 -> 415
I21: =IF(G21="",0,((E21/F21)*G21)) -> 0 | J21: =I21*H21 -> 0 | M21: Primary Line Current(L-L): | N21: =AQ21 -> 4.1737388 | O21: Amp | AQ21: =HLOOKUP($AT$6,$AR$17:$AU$26,5,0) -> 4.1737388 | AR21: =(S11*1000)/(1.732*N7) -> 4.1737388 | AS21: =AR21 -> 4.1737388 | AT21: =AR21 -> 4.1737388 | AU21: =AS21 -> 4.1737388
I22: =IF(G22="",0,((E22/F22)*G22)) -> 0 | J22: =I22*H22 -> 0 | M22: Primary Phase Current(L-P): | N22: =AQ22 -> 4.1737388 | O22: Amp | AQ22: =HLOOKUP($AT$6,$AR$17:$AU$26,6,0) -> 4.1737388 | AR22: =AR21 -> 4.1737388 | AS22: =AS21/1.732 -> 2.4097799 | AT22: =AR22 -> 4.1737388 | AU22: =AS22 -> 2.4097799
I23: =IF(G23="",0,((E23/F23)*G23)) -> 0 | J23: =I23*H23 -> 0 | M23: Secondary Line Voltage (L-L) | N23: =AQ23 -> 230 | O23: Volt | AQ23: =HLOOKUP($AT$6,$AR$17:$AU$26,7,0) -> 230 | AR23: =N8 -> 230 | AS23: =N8 -> 230 | AT23: =N8 -> 230 | AU23: =AR23 -> 230
I24: =IF(G24="",0,((E24/F24)*G24)) -> 0 | J24: =I24*H24 -> 0 | M24: Secondary Phase Voltage (L-P) | N24: =AQ24 -> 132.79446 | O24: Volt | AQ24: =HLOOKUP($AT$6,$AR$17:$AU$26,8,0) -> 132.79446 | AR24: =AR23/1.732 -> 132.79446 | AS24: =AS23 -> 230 | AT24: =AS24 -> 230 | AU24: =AR24 -> 132.79446
I25: =IF(G25="",0,((E25/F25)*G25)) -> 0 | J25: =I25*H25 -> 0 | M25: Secondary Phase Current(L-P): | N25: =AQ25 -> 7.5308766 | O25: Amp | AQ25: =HLOOKUP($AT$6,$AR$17:$AU$26,9,0) -> 7.5308766 | AR25: =(S11*1000)/(1.732*N8) -> 7.5308766 | AS25: =AR25 -> 7.5308766 | AT25: =AS25 -> 7.5308766 | AU25: =AR25 -> 7.5308766
I26: =IF(G26="",0,((E26/F26)*G26)) -> 0 | J26: =I26*H26 -> 0 | M26: Secondary Line Current(L-L): | N26: =AQ26 -> 7.5308766 | O26: Amp | AQ26: =HLOOKUP($AT$6,$AR$17:$AU$26,10,0) -> 7.5308766 | AR26: =AR25 -> 7.5308766 | AS26: =AS25/1.732 -> 4.3480812 | AT26: =AS26 -> 4.3480812 | AU26: =AR26 -> 7.5308766
I27: =IF(G27="",0,((E27/F27)*G27)) -> 0 | J27: =I27*H27 -> 0 | M27: Size of Circuit Breaker / Fuse (As per NEC 450.3)
I28: =IF(G28="",0,((E28/F28)*G28)) -> 0 | J28: =I28*H28 -> 0 | M28: =IF(AO10=TRUE,"Size of Circuit Breaker on Primary Side:","") -> Size of Circuit Breaker on Primary Side: | N28: =IF(N6=0,"",IF(M28="","",Sheet2!AZ11)) -> 6 | O28: =IF(N28="","","Amp") -> Amp
I29: =IF(G29="",0,((E29/F29)*G29)) -> 0 | J29: =I29*H29 -> 0 | M29: =IF(AO11=TRUE,"Size of Fuse on Primary Side:","") -> Size of Fuse on Primary Side: | N29: =IF(N6=0,"",IF(M29="","",Sheet2!BA11)) -> 6 | O29: =IF(N29="","","Amp") -> Amp
I30: =IF(G30="",0,((E30/F30)*G30)) -> 0 | J30: =I30*H30 -> 0 | M30: =IF(AO10=TRUE,"Size of Circuit Breaker on Secondary Side:","") -> Size of Circuit Breaker on Secondary Side: | N30: =IF(N6=0,"",IF(M30="","",Sheet2!BB11)) -> N/A | O30: =IF(N30="","","Amp") -> Amp
I31: =IF(G31="",0,((E31/F31)*G31)) -> 0 | J31: =I31*H31 -> 0 | M31: =IF(AO11=TRUE,"Size of Fuse on Secondary Side:","") -> Size of Fuse on Secondary Side: | N31: =IF(N6=0,"",IF(M31="","",Sheet2!BC11)) -> N/A | O31: =IF(N31="","","Amp") -> Amp
I32: =IF(G32="",0,((E32/F32)*G32)) -> 0 | J32: =I32*H32 -> 0 | M32: Transformer Losses
I33: =IF(G33="",0,((E33/F33)*G33)) -> 0 | J33: =I33*H33 -> 0 | M33: Total Losses@ Full Load | N33: =((1-(O12))/O12)*(S11*1000) -> 48.780488 | O33: Watt
I34: =IF(G34="",0,((E34/F34)*G34)) -> 0 | J34: =I34*H34 -> 0 | M34: Total Losses@ 1/4 Load | N34: =((1-(O13))/O13)*((S11*1000)/4) -> 19.230769 | O34: Watt
H35: Total Load (Kva) | J35: =SUM(J7:J34) -> 3 | M35: Full Load Copper Loss | N35: =(N33-N34)/(1-(1/16)) -> 31.5197 | O35: Watt
H36: Total Load D.F | J36: 1 | M36: Core Loss | N36: =N33-N35 -> 17.260788 | O36: Watt
H37: Total D.F (Kva) | J37: =J35*J36 -> 3

Sheet Sheet2
C2: Size of Transformer / Fuse / Circuit Breaker | AQ2: =IFERROR(AP4,0) -> 2
AP3: ='TC-C.B-Fuse'!N6 -> 3 | AQ3: =IF(AQ2=0,AR4,AQ4) -> 3
AK4: UnSupervised | AM4: Supervised | AP4: =MATCH(AP3,Sheet2!AP6:AP54,0) -> 2 | AQ4: =VLOOKUP('TC-C.B-Fuse'!N6,Sheet2!AP6:AQ54,2,TRUE) -> 3 | AR4: =VLOOKUP('TC-C.B-Fuse'!N6,Sheet2!AP6:AR54,3,TRUE) -> 6
C5: Standard Size of 3 Phase Transformer (KVA) | G5: Standard Size of Fuse / C.B (Amp) | AK5: Fuse / Inverse Time C.B as per NEC (Amp) | AM5: Fuse / Inverse Time C.B as per NEC (Amp) | AP5: 3 Phase T.C (KVA) | AT5: ='TC-C.B-Fuse'!AO9 -> 1 | AU5: Primary | AW5: Secondary | AZ5: ='TC-C.B-Fuse'!AO7 -> 0
C6: 1 | G6: 1 | AK6: =IF(G6="","",G6) -> 1 | AL6: =IF(AK6="","",AK6) -> 1 | AM6: =IF(G6="","",G6) -> 1 | AN6: =IF(AM6="","",AM6) -> 1 | AP6: =IF(C6="","",C6) -> 1 | AQ6: =IF(AP6="","",AP6) -> 1 | AR6: =IF(AP6="","",IF(AP7="",AP6,AP7)) -> 3 | AU6: C.B | AV6: Fuse | AW6: C.B | AX6: Fuse
C7: 3 | G7: 3 | AK7: =IF(G7="","",G7) -> 3 | AL7: =IF(AK7="","",IF(AK8="",AK7,AK8)) -> 6 | AM7: =IF(G7="","",G7) -> 3 | AN7: =IF(AM7="","",AM7) -> 3 | AP7: =IF(C7="","",C7) -> 3 | AQ7: =IF(AP7="","",AP7) -> 3 | AR7: =IF(AP7="","",IF(AP8="",AP7,AP8)) -> 6 | AT7: 1 | AU7: =AX33 -> 6 | AV7: =AZ33 -> 3 | AW7: =AX34 -> 2.5 | AX7: =AZ34 -> 2.5
C8: 6 | G8: 6 | AK8: =IF(G8="","",G8) -> 6 | AL8: =IF(AK8="","",IF(AK9="",AK8,AK9)) -> 10 | AM8: =IF(G8="","",G8) -> 6 | AN8: =IF(AM8="","",AM8) -> 6 | AP8: =IF(C8="","",C8) -> 6 | AQ8: =IF(AP8="","",AP8) -> 6 | AR8: =IF(AP8="","",IF(AP9="",AP8,AP9)) -> 9 | AT8: 2 | AU8: =AX39 -> 6 | AV8: =AZ39 -> 3 | AW8: =AX40 -> 1.25 | AX8: =AZ40 -> 1.25
C9: 9 | G9: 10 | AK9: =IF(G9="","",G9) -> 10 | AL9: =IF(AK9="","",IF(AK10="",AK9,AK10)) -> 15 | AM9: =IF(G9="","",G9) -> 10 | AN9: =IF(AM9="","",AM9) -> 10 | AP9: =IF(C9="","",C9) -> 9 | AQ9: =IF(AP9="","",AP9) -> 9 | AR9: =IF(AP9="","",IF(AP10="",AP9,AP10)) -> 15 | AU9: =IF('TC-C.B-Fuse'!AO9=1,Sheet2!AU7,Sheet2!AU8) -> 6 | AV9: =IF('TC-C.B-Fuse'!AO9=1,Sheet2!AV7,AV8) -> 3 | AW9: =IF('TC-C.B-Fuse'!AO9=1,AW7,AW8) -> 2.5 | AX9: =IF('TC-C.B-Fuse'!AO9=1,AX7,AX8) -> 2.5 | AZ9: Primary | BB9: Secondary
C10: 15 | G10: 15 | AK10: =IF(G10="","",G10) -> 15 | AL10: =IF(AK10="","",IF(AK11="",AK10,AK11)) -> 20 | AM10: =IF(G10="","",G10) -> 15 | AN10: =IF(AM10="","",AM10) -> 15 | AP10: =IF(C10="","",C10) -> 15 | AQ10: =IF(AP10="","",AP10) -> 15 | AR10: =IF(AP10="","",IF(AP11="",AP10,AP11)) -> 25 | AU10: ='TC-C.B-Fuse'!N21*Sheet2!AU9 -> 25.042433 | AV10: ='TC-C.B-Fuse'!N21*Sheet2!AV9 -> 12.521217 | AW10: ='TC-C.B-Fuse'!N25*Sheet2!AW9 -> 18.827191 | AX10: ='TC-C.B-Fuse'!N25*Sheet2!AX9 -> 18.827191 | AZ10: C.B | BA10: Fuse | BB10: C.B | BC10: Fuse
C11: 25 | G11: 20 | AK11: =IF(G11="","",G11) -> 20 | AL11: =IF(AK11="","",IF(AK12="",AK11,AK12)) -> 25 | AM11: =IF(G11="","",G11) -> 20 | AN11: =IF(AM11="","",AM11) -> 20 | AP11: =IF(C11="","",C11) -> 25 | AQ11: =IF(AP11="","",AP11) -> 25 | AR11: =IF(AP11="","",IF(AP12="",AP11,AP12)) -> 30 | AU11: =IF(AT5=1,(VLOOKUP(AU10,AM6:AN60,2,TRUE)),(VLOOKUP(AU10,AK6:AL60,2,TRUE))) -> 25 | AV11: =IF(AT5=1,(VLOOKUP(AV10,AM6:AN60,2,TRUE)),(VLOOKUP(AV10,AK6:AL60,2,TRUE))) -> 10 | AW11: =IF(AT5=1,(VLOOKUP(AW10,AM6:AN60,2,TRUE)),(VLOOKUP(AW10,AK6:AL60,2,TRUE))) -> 15 | AX11: =IF(AT5=1,(VLOOKUP(AX10,AM6:AN60,2,TRUE)),(VLOOKUP(AX10,AK6:AL60,2,TRUE))) -> 15 | AZ11: =IF($AZ$5=1,AU11,AV121) -> 6 | BA11: =IF($AZ$5=1,AV11,AV121) -> 6 | BB11: =IF($AZ$5=1,AW11,AW121) -> N/A | BC11: =IF($AZ$5=1,AX11,AW121) -> N/A
C12: 30 | G12: 25 | AK12: =IF(G12="","",G12) -> 25 | AL12: =IF(AK12="","",IF(AK13="",AK12,AK13)) -> 30 | AM12: =IF(G12="","",G12) -> 25 | AN12: =IF(AM12="","",AM12) -> 25 | AP12: =IF(C12="","",C12) -> 30 | AQ12: =IF(AP12="","",AP12) -> 30 | AR12: =IF(AP12="","",IF(AP13="",AP12,AP13)) -> 37.5
C13: 37.5 | G13: 30 | AK13: =IF(G13="","",G13) -> 30 | AL13: =IF(AK13="","",IF(AK14="",AK13,AK14)) -> 35 | AM13: =IF(G13="","",G13) -> 30 | AN13: =IF(AM13="","",AM13) -> 30 | AP13: =IF(C13="","",C13) -> 37.5 | AQ13: =IF(AP13="","",AP13) -> 37.5 | AR13: =IF(AP13="","",IF(AP14="",AP13,AP14)) -> 45
C14: 45 | G14: 35 | AK14: =IF(G14="","",G14) -> 35 | AL14: =IF(AK14="","",IF(AK15="",AK14,AK15)) -> 40 | AM14: =IF(G14="","",G14) -> 35 | AN14: =IF(AM14="","",AM14) -> 35 | AP14: =IF(C14="","",C14) -> 45 | AQ14: =IF(AP14="","",AP14) -> 45 | AR14: =IF(AP14="","",IF(AP15="",AP14,AP15)) -> 50
C15: 50 | G15: 40 | AK15: =IF(G15="","",G15) -> 40 | AL15: =IF(AK15="","",IF(AK16="",AK15,AK16)) -> 45 | AM15: =IF(G15="","",G15) -> 40 | AN15: =IF(AM15="","",AM15) -> 40 | AP15: =IF(C15="","",C15) -> 50 | AQ15: =IF(AP15="","",AP15) -> 50 | AR15: =IF(AP15="","",IF(AP16="",AP15,AP16)) -> 75 | AU15: More Than 600V | AY15: Supervised
C16: 75 | G16: 45 | AK16: =IF(G16="","",G16) -> 45 | AL16: =IF(AK16="","",IF(AK17="",AK16,AK17)) -> 50 | AM16: =IF(G16="","",G16) -> 45 | AN16: =IF(AM16="","",AM16) -> 45 | AP16: =IF(C16="","",C16) -> 75 | AQ16: =IF(AP16="","",AP16) -> 75 | AR16: =IF(AP16="","",IF(AP17="",AP16,AP17)) -> 112.5 | AU16: %Imp | AV16: Primary | AX16: secondary
C17: 112.5 | G17: 50 | AK17: =IF(G17="","",G17) -> 50 | AL17: =IF(AK17="","",IF(AK18="",AK17,AK18)) -> 60 | AM17: =IF(G17="","",G17) -> 50 | AN17: =IF(AM17="","",AM17) -> 50 | AP17: =IF(C17="","",C17) -> 112.5 | AQ17: =IF(AP17="","",AP17) -> 112.5 | AR17: =IF(AP17="","",IF(AP18="",AP17,AP18)) -> 150 | AV17: >600 | AX17: >600 | AZ17: <600
C18: 150 | G18: 60 | AK18: =IF(G18="","",G18) -> 60 | AL18: =IF(AK18="","",IF(AK19="",AK18,AK19)) -> 70 | AM18: =IF(G18="","",G18) -> 60 | AN18: =IF(AM18="","",AM18) -> 60 | AP18: =IF(C18="","",C18) -> 150 | AQ18: =IF(AP18="","",AP18) -> 150 | AR18: =IF(AP18="","",IF(AP19="",AP18,AP19)) -> 225 | AV18: C.B | AW18: Fuse | AX18: C.B | AY18: Fuse | AZ18: C.B/Fuse
C19: 225 | G19: 70 | AK19: =IF(G19="","",G19) -> 70 | AL19: =IF(AK19="","",IF(AK20="",AK19,AK20)) -> 80 | AM19: =IF(G19="","",G19) -> 70 | AN19: =IF(AM19="","",AM19) -> 70 | AP19: =IF(C19="","",C19) -> 225 | AQ19: =IF(AP19="","",AP19) -> 225 | AR19: =IF(AP19="","",IF(AP20="",AP19,AP20)) -> 300
C20: 300 | G20: 80 | AK20: =IF(G20="","",G20) -> 80 | AL20: =IF(AK20="","",IF(AK21="",AK20,AK21)) -> 90 | AM20: =IF(G20="","",G20) -> 80 | AN20: =IF(AM20="","",AM20) -> 80 | AP20: =IF(C20="","",C20) -> 300 | AQ20: =IF(AP20="","",AP20) -> 300 | AR20: =IF(AP20="","",IF(AP21="",AP20,AP21)) -> 500 | AU20: 0.01 | AV20: 6 | AW20: 3 | AX20: 3 | AY20: 2.5 | AZ20: 2.5
C21: 500 | G21: 90 | AK21: =IF(G21="","",G21) -> 90 | AL21: =IF(AK21="","",IF(AK22="",AK21,AK22)) -> 100 | AM21: =IF(G21="","",G21) -> 90 | AN21: =IF(AM21="","",AM21) -> 90 | AP21: =IF(C21="","",C21) -> 500 | AQ21: =IF(AP21="","",AP21) -> 500 | AR21: =IF(AP21="","",IF(AP22="",AP21,AP22)) -> 750 | AU21: 0.02 | AV21: 6 | AW21: 3 | AX21: 3 | AY21: 2.5 | AZ21: 2.5
C22: 750 | G22: 100 | AK22: =IF(G22="","",G22) -> 100 | AL22: =IF(AK22="","",IF(AK23="",AK22,AK23)) -> 110 | AM22: =IF(G22="","",G22) -> 100 | AN22: =IF(AM22="","",AM22) -> 100 | AP22: =IF(C22="","",C22) -> 750 | AQ22: =IF(AP22="","",AP22) -> 750 | AR22: =IF(AP22="","",IF(AP23="",AP22,AP23)) -> 1000 | AU22: 0.03 | AV22: 6 | AW22: 3 | AX22: 3 | AY22: 2.5 | AZ22: 2.5
C23: 1000 | G23: 110 | AK23: =IF(G23="","",G23) -> 110 | AL23: =IF(AK23="","",IF(AK24="",AK23,AK24)) -> 125 | AM23: =IF(G23="","",G23) -> 110 | AN23: =IF(AM23="","",AM23) -> 110 | AP23: =IF(C23="","",C23) -> 1000 | AQ23: =IF(AP23="","",AP23) -> 1000 | AR23: =IF(AP23="","",IF(AP24="",AP23,AP24)) -> 1500 | AU23: 0.04 | AV23: 6 | AW23: 3 | AX23: 3 | AY23: 2.5 | AZ23: 2.5
C24: 1500 | G24: 125 | AK24: =IF(G24="","",G24) -> 125 | AL24: =IF(AK24="","",IF(AK25="",AK24,AK25)) -> 150 | AM24: =IF(G24="","",G24) -> 125 | AN24: =IF(AM24="","",AM24) -> 125 | AP24: =IF(C24="","",C24) -> 1500 | AQ24: =IF(AP24="","",AP24) -> 1500 | AR24: =IF(AP24="","",IF(AP25="",AP24,AP25)) -> 2000 | AU24: 0.05 | AV24: 6 | AW24: 3 | AX24: 3 | AY24: 2.5 | AZ24: 2.5
C25: 2000 | G25: 150 | AK25: =IF(G25="","",G25) -> 150 | AL25: =IF(AK25="","",IF(AK26="",AK25,AK26)) -> 160 | AM25: =IF(G25="","",G25) -> 150 | AN25: =IF(AM25="","",AM25) -> 150 | AP25: =IF(C25="","",C25) -> 2000 | AQ25: =IF(AP25="","",AP25) -> 2000 | AR25: =IF(AP25="","",IF(AP26="",AP25,AP26)) -> 2500 | AU25: 0.06 | AV25: 6 | AW25: 3 | AX25: 3 | AY25: 2.5 | AZ25: 2.5
C26: 2500 | G26: 160 | AK26: =IF(G26="","",G26) -> 160 | AL26: =IF(AK26="","",IF(AK27="",AK26,AK27)) -> 175 | AM26: =IF(G26="","",G26) -> 160 | AN26: =IF(AM26="","",AM26) -> 160 | AP26: =IF(C26="","",C26) -> 2500 | AQ26: =IF(AP26="","",AP26) -> 2500 | AR26: =IF(AP26="","",IF(AP27="",AP26,AP27)) -> 3750 | AU26: 0.07 | AV26: 4 | AW26: 3 | AX26: 2.5 | AY26: 2.25 | AZ26: 2.5
C27: 3750 | G27: 175 | AK27: =IF(G27="","",G27) -> 175 | AL27: =IF(AK27="","",IF(AK28="",AK27,AK28)) -> 200 | AM27: =IF(G27="","",G27) -> 175 | AN27: =IF(AM27="","",AM27) -> 175 | AP27: =IF(C27="","",C27) -> 3750 | AQ27: =IF(AP27="","",AP27) -> 3750 | AR27: =IF(AP27="","",IF(AP28="",AP27,AP28)) -> 5000 | AU27: 0.08 | AV27: 4 | AW27: 3 | AX27: 2.5 | AY27: 2.25 | AZ27: 2.5
C28: 5000 | G28: 200 | AK28: =IF(G28="","",G28) -> 200 | AL28: =IF(AK28="","",IF(AK29="",AK28,AK29)) -> 225 | AM28: =IF(G28="","",G28) -> 200 | AN28: =IF(AM28="","",AM28) -> 200 | AP28: =IF(C28="","",C28) -> 5000 | AQ28: =IF(AP28="","",AP28) -> 5000 | AR28: =IF(AP28="","",IF(AP29="",AP28,AP29)) -> 7500 | AU28: 0.09 | AV28: 4 | AW28: 3 | AX28: 2.5 | AY28: 2.25 | AZ28: 2.5
C29: 7500 | G29: 225 | AK29: =IF(G29="","",G29) -> 225 | AL29: =IF(AK29="","",IF(AK30="",AK29,AK30)) -> 250 | AM29: =IF(G29="","",G29) -> 225 | AN29: =IF(AM29="","",AM29) -> 225 | AP29: =IF(C29="","",C29) -> 7500 | AQ29: =IF(AP29="","",AP29) -> 7500 | AR29: =IF(AP29="","",IF(AP30="",AP29,AP30)) -> 10000 | AU29: 0.1 | AV29: 4 | AW29: 3 | AX29: 2.5 | AY29: 2.25 | AZ29: 2.5
C30: 10000 | G30: 250 | AK30: =IF(G30="","",G30) -> 250 | AL30: =IF(AK30="","",IF(AK31="",AK30,AK31)) -> 300 | AM30: =IF(G30="","",G30) -> 250 | AN30: =IF(AM30="","",AM30) -> 250 | AP30: =IF(C30="","",C30) -> 10000 | AQ30: =IF(AP30="","",AP30) -> 10000 | AR30: =IF(AP30="","",IF(AP31="",AP30,AP31)) -> 12000
C31: 12000 | G31: 300 | AK31: =IF(G31="","",G31) -> 300 | AL31: =IF(AK31="","",IF(AK32="",AK31,AK32)) -> 350 | AM31: =IF(G31="","",G31) -> 300 | AN31: =IF(AM31="","",AM31) -> 300 | AP31: =IF(C31="","",C31) -> 12000 | AQ31: =IF(AP31="","",AP31) -> 12000 | AR31: =IF(AP31="","",IF(AP32="",AP31,AP32)) -> 15000
C32: 15000 | G32: 350 | AK32: =IF(G32="","",G32) -> 350 | AL32: =IF(AK32="","",IF(AK33="",AK32,AK33)) -> 400 | AM32: =IF(G32="","",G32) -> 350 | AN32: =IF(AM32="","",AM32) -> 350 | AP32: =IF(C32="","",C32) -> 15000 | AQ32: =IF(AP32="","",AP32) -> 15000 | AR32: =IF(AP32="","",IF(AP33="",AP32,AP33)) -> 20000
C33: 20000 | G33: 400 | AK33: =IF(G33="","",G33) -> 400 | AL33: =IF(AK33="","",IF(AK34="",AK33,AK34)) -> 450 | AM33: =IF(G33="","",G33) -> 400 | AN33: =IF(AM33="","",AM33) -> 400 | AP33: =IF(C33="","",C33) -> 20000 | AQ33: =IF(AP33="","",AP33) -> 20000 | AR33: =IF(AP33="","",IF(AP34="",AP33,AP34)) -> 25000 | AT33: Prim. | AU33: ='TC-C.B-Fuse'!N9 -> 0.05 | AV33: ='TC-C.B-Fuse'!AO7 -> 0 | AW33: C.B | AX33: =VLOOKUP(AU33,AU20:AZ29,2,TRUE) -> 6 | AY33: Fuse | AZ33: =VLOOKUP(AU33,AU20:AZ29,3,TRUE) -> 3
C34: 25000 | G34: 450 | AK34: =IF(G34="","",G34) -> 450 | AL34: =IF(AK34="","",IF(AK35="",AK34,AK35)) -> 500 | AM34: =IF(G34="","",G34) -> 450 | AN34: =IF(AM34="","",AM34) -> 450 | AP34: =IF(C34="","",C34) -> 25000 | AQ34: =IF(AP34="","",AP34) -> 25000 | AR34: =IF(AP34="","",IF(AP35="",AP34,AP35)) -> 30000 | AT34: Sec. | AV34: ='TC-C.B-Fuse'!AO8 -> 0 | AW34: C.B | AX34: =IF(AV34=0,(VLOOKUP(AU33,AU20:AZ29,6,TRUE)),(VLOOKUP(AU33,AU20:AZ29,4,TRUE))) -> 2.5 | AY34: Fuse | AZ34: =IF(AV34=0,(VLOOKUP(AU33,AU20:AZ29,6,TRUE)),(VLOOKUP(AU33,AU20:AZ29,5,TRUE))) -> 2.5
C35: 30000 | G35: 500 | AK35: =IF(G35="","",G35) -> 500 | AL35: =IF(AK35="","",IF(AK36="",AK35,AK36)) -> 600 | AM35: =IF(G35="","",G35) -> 500 | AN35: =IF(AM35="","",AM35) -> 500 | AP35: =IF(C35="","",C35) -> 30000 | AQ35: =IF(AP35="","",AP35) -> 30000 | AR35: =IF(AP35="","",IF(AP36="",AP35,AP36)) -> 37500
C36: 37500 | G36: 600 | AK36: =IF(G36="","",G36) -> 600 | AL36: =IF(AK36="","",IF(AK37="",AK36,AK37)) -> 700 | AM36: =IF(G36="","",G36) -> 600 | AN36: =IF(AM36="","",AM36) -> 600 | AP36: =IF(C36="","",C36) -> 37500 | AQ36: =IF(AP36="","",AP36) -> 37500 | AR36: =IF(AP36="","",IF(AP37="",AP36,AP37)) -> 50000
C37: 50000 | G37: 700 | AK37: =IF(G37="","",G37) -> 700 | AL37: =IF(AK37="","",IF(AK38="",AK37,AK38)) -> 800 | AM37: =IF(G37="","",G37) -> 700 | AN37: =IF(AM37="","",AM37) -> 700 | AP37: =IF(C37="","",C37) -> 50000 | AQ37: =IF(AP37="","",AP37) -> 50000 | AR37: =IF(AP37="","",IF(AP38="",AP37,AP38)) -> 60000
C38: 60000 | G38: 800 | AK38: =IF(G38="","",G38) -> 800 | AL38: =IF(AK38="","",IF(AK39="",AK38,AK39)) -> 1000 | AM38: =IF(G38="","",G38) -> 800 | AN38: =IF(AM38="","",AM38) -> 800 | AP38: =IF(C38="","",C38) -> 60000 | AQ38: =IF(AP38="","",AP38) -> 60000 | AR38: =IF(AP38="","",IF(AP39="",AP38,AP39)) -> 75000
C39: 75000 | G39: 1000 | AK39: =IF(G39="","",G39) -> 1000 | AL39: =IF(AK39="","",IF(AK40="",AK39,AK40)) -> 1200 | AM39: =IF(G39="","",G39) -> 1000 | AN39: =IF(AM39="","",AM39) -> 1000 | AP39: =IF(C39="","",C39) -> 75000 | AQ39: =IF(AP39="","",AP39) -> 75000 | AR39: =IF(AP39="","",IF(AP40="",AP39,AP40)) -> 100000 | AT39: Prim. | AU39: ='TC-C.B-Fuse'!N9 -> 0.05 | AV39: ='TC-C.B-Fuse'!AO7 -> 0 | AW39: C.B | AX39: =VLOOKUP(AU39,AU65:AZ74,2,TRUE) -> 6 | AY39: Fuse | AZ39: =VLOOKUP(AU39,AU65:AZ74,3,TRUE) -> 3
C40: 100000 | G40: 1200 | AK40: =IF(G40="","",G40) -> 1200 | AL40: =IF(AK40="","",IF(AK41="",AK40,AK41)) -> 1600 | AM40: =IF(G40="","",G40) -> 1200 | AN40: =IF(AM40="","",AM40) -> 1200 | AP40: =IF(C40="","",C40) -> 100000 | AQ40: =IF(AP40="","",AP40) -> 100000 | AR40: =IF(AP40="","",IF(AP41="",AP40,AP41)) -> 100000 | AT40: Sec. | AV40: ='TC-C.B-Fuse'!AO8 -> 0 | AW40: C.B | AX40: =IF(AV40=0,(VLOOKUP(AU39,AU65:AZ74,6,TRUE)),(VLOOKUP(AU39,AU65:AZ74,4,TRUE))) -> 1.25 | AY40: Fuse | AZ40: =IF(AV40=0,(VLOOKUP(AU39,AU65:AZ74,6,TRUE)),(VLOOKUP(AU39,AU65:AZ74,5,TRUE))) -> 1.25
G41: 1600 | AK41: =IF(G41="","",G41) -> 1600 | AL41: =IF(AK41="","",IF(AK42="",AK41,AK42)) -> 2000 | AM41: =IF(G41="","",G41) -> 1600 | AN41: =IF(AM41="","",AM41) -> 1600 | AP41: =IF(C41="","",C41) | AQ41: =IF(AP41="","",AP41) | AR41: =IF(AP41="","",IF(AP42="",AP41,AP42))
...
